Workbook
Name Finance: 'Dept,Desig'!$E$2:$E$9
Name HR: 'Dept,Desig'!$F$2:$F$9
Name IT: 'Dept,Desig'!$D$2:$D$15
Name Marketing: 'Dept,Desig'!$G$2:$G$7
Name Operations: 'Dept,Desig'!$C$2:$C$9
Name Sales: 'Dept,Desig'!$B$2:$B$11

Sheet Employee data
A1: 1 | B1: 2 | C1: 3 | D1: 4 | E1: 5 | F1: 6 | G1: 7 | H1: 8 | I1: 9 | J1: 10 | K1: 11 | L1: 12 | M1: 13 | N1: 14 | O1: 15 | P1: 16 | Q1: 17 | R1: 18 | S1: 19 | T1: 20 | U1: 21 | V1: 22 | W1: 23 | X1: 24 | Y1: 25 | Z1: 26
A2: EmployeeID | B2: EmployeeName | C2: DepartmentID | D2: Designation | E2: Gender | F2: DOB | G2: DOJ | H2: Department | I2: Email ID | J2: Expereince | K2: Employee rating | L2: Attendance | M2: BasicPay | N2: HRA | O2: Allowance | P2: 1. Bonus | Q2: Bonus Amount | R2: 3. Performance Incentive | S2: Gross Salary | T2: PFPct | U2: PF Deduction | V2: OtherDeduction | W2: 2. Income Tax | X2: Tax amount | Y2: 4. Leave Bonus Eligibility | Z2: Net Salary
A3: EMP001 | B3: Arun Kumar | C3: D001 | D3: Analyst | E3: M | F3: 34801 | G3: 44361 | H3: =VLOOKUP(TRIM('Employee data'!$C3),$A$108:$B$113,2,FALSE) -> IT | I3: emp001@abc.com | J3: =ROUND(YEARFRAC('Employee data'!$G3,TODAY()),2) -> 5.14 | K3: 4.2 | L3: 96 | M3: 35000 | N3: 12000 | O3: 5000 | P3: =IF('Employee data'!$M3>=50000,"10%","5%") -> 5% | Q3: =M3*P3 -> 1750 | R3: =IF(AND('Employee data'!$K3>=4,'Employee data'!$L3>=95),5000,0) -> 5000 | S3: =M3+N3+O3+Q3+R3 -> 58750 | T3: 12 | U3: ='Employee data'!$M3/'Employee data'!$T3 -> 2916.6667 | V3: 1000 | W3: =IF('Employee data'!$S3>=80000,20%,IF('Employee data'!$S3>=50000,10%,5%)) -> 0.1 | X3: =S3*W3 -> 5875 | Y3: =IF(OR('Employee data'!$J3>5,'Employee data'!$L3>98),"Eligible","Not Eligible") -> Eligible | Z3: =S3-X3-U3-V3 -> 48958.333
A4: EMP002 | B4: Priya S | C4: D002 | D4: Executive | E4: F | F4: 34595 | G4: 43912 | H4: =VLOOKUP(TRIM('Employee data'!$C4),$A$108:$B$113,2,FALSE) -> HR | I4: emp002@abc.com | J4: =ROUND(YEARFRAC('Employee data'!$G4,TODAY()),2) -> 6.37 | K4: 3.8 | L4: 94 | M4: 42000 | N4: 15000 | O4: 6000 | P4: =IF('Employee data'!$M4>=50000,"10%","5%") -> 5% | Q4: =M4*P4 -> 2100 | R4: =IF(AND('Employee data'!$K4>=4,'Employee data'!$L4>=95),5000,0) -> 0 | S4: =M4+N4+O4+Q4+R4 -> 65100 | T4: 12 | U4: ='Employee data'!$M4/'Employee data'!$T4 -> 3500 | V4: 1200 | W4: =IF('Employee data'!$S4>=80000,20%,IF('Employee data'!$S4>=50000,10%,5%)) -> 0.1 | X4: =S4*W4 -> 6510 | Y4: =IF(OR('Employee data'!$J4>5,'Employee data'!$L4>98),"Eligible","Not Eligible") -> Eligible | Z4: =S4-X4-U4-V4 -> 53890
A5: EMP003 | B5: Vikram Raj | C5: D003 | D5: Accountant | E5: M | F5: 33788 | G5: 43779 | H5: =VLOOKUP(TRIM('Employee data'!$C5),$A$108:$B$113,2,FALSE) -> Finance | I5: emp003@abc.com | J5: =ROUND(YEARFRAC('Employee data'!$G5,TODAY()),2) -> 6.74 | K5: 4.6 | L5: 98 | M5: 48000 | N5: 16000 | O5: 7000 | P5: =IF('Employee data'!$M5>=50000,"10%","5%") -> 5% | Q5: =M5*P5 -> 2400 | R5: =IF(AND('Employee data'!$K5>=4,'Employee data'!$L5>=95),5000,0) -> 5000 | S5: =M5+N5+O5+Q5+R5 -> 78400 | T5: 12 | U5: ='Employee data'!$M5/'Employee data'!$T5 -> 4000 | V5: 1500 | W5: =IF('Employee data'!$S5>=80000,20%,IF('Employee data'!$S5>=50000,10%,5%)) -> 0.1 | X5: =S5*W5 -> 7840 | Y5: =IF(OR('Employee data'!$J5>5,'Employee data'!$L5>98),"Eligible","Not Eligible") -> Eligible | Z5: =S5-X5-U5-V5 -> 65060
A6: EMP004 | B6: Anita Sharma | C6: D004 | D6: Sales Executive | E6: F | F6: 35116 | G6: 44566 | H6: =VLOOKUP(TRIM('Employee data'!$C6),$A$108:$B$113,2,FALSE) -> Sales | I6: emp004@abc.com | J6: =ROUND(YEARFRAC('Employee data'!$G6,TODAY()),2) -> 4.59 | K6: 3.4 | L6: 91 | M6: 30000 | N6: 10000 | O6: 4000 | P6: =IF('Employee data'!$M6>=50000,"10%","5%") -> 5% | Q6: =M6*P6 -> 1500 | R6: =IF(AND('Employee data'!$K6>=4,'Employee data'!$L6>=95),5000,0) -> 0 | S6: =M6+N6+O6+Q6+R6 -> 45500 | T6: 12 | U6: ='Employee data'!$M6/'Employee data'!$T6 -> 2500 | V6: 800 | W6: =IF('Employee data'!$S6>=80000,20%,IF('Employee data'!$S6>=50000,10%,5%)) -> 0.05 | X6: =S6*W6 -> 2275 | Y6: =IF(OR('Employee data'!$J6>5,'Employee data'!$L6>98),"Eligible","Not Eligible") -> Not Eligible | Z6: =S6-X6-U6-V6 -> 39925
A7: EMP005 | B7: Rohit Verma | C7: D005 | D7: Coordinator | E7: M | F7: 34333 | G7: 43331 | H7: =VLOOKUP(TRIM('Employee data'!$C7),$A$108:$B$113,2,FALSE) -> Operations | I7: emp005@abc.com | J7: =ROUND(YEARFRAC('Employee data'!$G7,TODAY()),2) -> 7.96 | K7: 4 | L7: 95 | M7: 39000 | N7: 13000 | O7: 5500 | P7: =IF('Employee data'!$M7>=50000,"10%","5%") -> 5% | Q7: =M7*P7 -> 1950 | R7: =IF(AND('Employee data'!$K7>=4,'Employee data'!$L7>=95),5000,0) -> 5000 | S7: =M7+N7+O7+Q7+R7 -> 64450 | T7: 12 | U7: ='Employee data'!$M7/'Employee data'!$T7 -> 3250 | V7: 1100 | W7: =IF('Employee data'!$S7>=80000,20%,IF('Employee data'!$S7>=50000,10%,5%)) -> 0.1 | X7: =S7*W7 -> 6445 | Y7: =IF(OR('Employee data'!$J7>5,'Employee data'!$L7>98),"Eligible","Not Eligible") -> Eligible | Z7: =S7-X7-U7-V7 -> 53655
A8: EMP006 | B8: Sneha Iyer | C8: D006 | D8: Support Engineer | E8: F | F8: 34833 | G8: 44298 | H8: =VLOOKUP(TRIM('Employee data'!$C8),$A$108:$B$113,2,FALSE) -> Support | I8: emp006@abc.com | J8: =ROUND(YEARFRAC('Employee data'!$G8,TODAY()),2) -> 5.32 | K8: 3.9 | L8: 93 | M8: 36000 | N8: 12500 | O8: 5000 | P8: =IF('Employee data'!$M8>=50000,"10%","5%") -> 5% | Q8: =M8*P8 -> 1800 | R8: =IF(AND('Employee data'!$K8>=4,'Employee data'!$L8>=95),5000,0) -> 0 | S8: =M8+N8+O8+Q8+R8 -> 55300 | T8: 12 | U8: ='Employee data'!$M8/'Employee data'!$T8 -> 3000 | V8: 900 | W8: =IF('Employee data'!$S8>=80000,20%,IF('Employee data'!$S8>=50000,10%,5%)) -> 0.1 | X8: =S8*W8 -> 5530 | Y8: =IF(OR('Employee data'!$J8>5,'Employee data'!$L8>98),"Eligible","Not Eligible") -> Eligible | Z8: =S8-X8-U8-V8 -> 45870
A9: EMP007 | B9: Karthik M | C9: D001 | D9: Developer | E9: M | F9: 33536 | G9: 42917 | H9: =VLOOKUP(TRIM('Employee data'!$C9),$A$108:$B$113,2,FALSE) -> IT | I9: emp007@abc.com | J9: =ROUND(YEARFRAC('Employee data'!$G9,TODAY()),2) -> 9.1 | K9: 4.8 | L9: 99 | M9: 55000 | N9: 18000 | O9: 9000 | P9: =IF('Employee data'!$M9>=50000,"10%","5%") -> 10% | Q9: =M9*P9 -> 5500 | R9: =IF(AND('Employee data'!$K9>=4,'Employee data'!$L9>=95),5000,0) -> 5000 | S9: =M9+N9+O9+Q9+R9 -> 92500 | T9: 12 | U9: ='Employee data'!$M9/'Employee data'!$T9 -> 4583.3333 | V9: 2000 | W9: =IF('Employee data'!$S9>=80000,20%,IF('Employee data'!$S9>=50000,10%,5%)) -> 0.2 | X9: =S9*W9 -> 18500 | Y9: =IF(OR('Employee data'!$J9>5,'Employee data'!$L9>98),"Eligible","Not Eligible") -> Eligible | Z9: =S9-X9-U9-V9 -> 67416.667
A10: EMP008 | B10: Meera Nair | C10: D002 | D10: HR Analyst | E10: F | F10: 35439 | G10: 44970 | H10: =VLOOKUP(TRIM('Employee data'!$C10),$A$108:$B$113,2,FALSE) -> HR | I10: emp008@abc.com | J10: =ROUND(YEARFRAC('Employee data'!$G10,TODAY()),2) -> 3.48 | K10: 3.7 | L10: 92 | M10: 38000 | N10: 14000 | O10: 4500 | P10: =IF('Employee data'!$M10>=50000,"10%","5%") -> 5% | Q10: =M10*P10 -> 1900 | R10: =IF(AND('Employee data'!$K10>=4,'Employee data'!$L10>=95),5000,0) -> 0 | S10: =M10+N10+O10+Q10+R10 -> 58400 | T10: 12 | U10: ='Employee data'!$M10/'Employee data'!$T10 -> 3166.6667 | V10: 1000 | W10: =IF('Employee data'!$S10>=80000,20%,IF('Employee data'!$S10>=50000,10%,5%)) -> 0.1 | X10: =S10*W10 -> 5840 | Y10: =IF(OR('Employee data'!$J10>5,'Employee data'!$L10>98),"Eligible","Not Eligible") -> Not Eligible | Z10: =S10-X10-U10-V10 -> 48393.333
A11: EMP009 | B11: Sanjay P | C11: D003 | D11: Senior Accountant | E11: M | F11: 33041 | G11: 42639 | H11: =VLOOKUP(TRIM('Employee data'!$C11),$A$108:$B$113,2,FALSE) -> Finance | I11: emp009@abc.com | J11: =ROUND(YEARFRAC('Employee data'!$G11,TODAY()),2) -> 9.86 | K11: 4.9 | L11: 97 | M11: 62000 | N11: 20000 | O11: 10000 | P11: =IF('Employee data'!$M11>=50000,"10%","5%") -> 10% | Q11: =M11*P11 -> 6200 | R11: =IF(AND('Employee data'!$K11>=4,'Employee data'!$L11>=95),5000,0) -> 5000 | S11: =M11+N11+O11+Q11+R11 -> 103200 | T11: 12 | U11: ='Employee data'!$M11/'Employee data'!$T11 -> 5166.6667 | V11: 2500 | W11: =IF('Employee data'!$S11>=80000,20%,IF('Employee data'!$S11>=50000,10%,5%)) -> 0.2 | X11: =S11*W11 -> 20640 | Y11: =IF(OR('Employee data'!$J11>5,'Employee data'!$L11>98),"Eligible","Not Eligible") -> Eligible | Z11: =S11-X11-U11-V11 -> 74893.333
A12: EMP010 | B12: Divya R | C12: D004 | D12: Sales Executive | E12: F | F12: 36127 | G12: 44732 | H12: =VLOOKUP(TRIM('Employee data'!$C12),$A$108:$B$113,2,FALSE) -> Sales | I12: emp010@abc.com | J12: =ROUND(YEARFRAC('Employee data'!$G12,TODAY()),2) -> 4.13 | K12: 3.5 | L12: 90 | M12: 31000 | N12: 10500 | O12: 4000 | P12: =IF('Employee data'!$M12>=50000,"10%","5%") -> 5% | Q12: =M12*P12 -> 1550 | R12: =IF(AND('Employee data'!$K12>=4,'Employee data'!$L12>=95),5000,0) -> 0 | S12: =M12+N12+O12+Q12+R12 -> 47050 | T12: 12 | U12: ='Employee data'!$M12/'Employee data'!$T12 -> 2583.3333 | V12: 850 | W12: =IF('Employee data'!$S12>=80000,20%,IF('Employee data'!$S12>=50000,10%,5%)) -> 0.05 | X12: =S12*W12 -> 2352.5 | Y12: =IF(OR('Employee data'!$J12>5,'Employee data'!$L12>98),"Eligible","Not Eligible") -> Not Eligible | Z12: =S12-X12-U12-V12 -> 41264.167
A13: EMP011 | B13: Manoj T | C13: D005 | D13: Supervisor | E13: M | F13: 33677 | G13: 43507 | H13: =VLOOKUP(TRIM('Employee data'!$C13),$A$108:$B$113,2,FALSE) -> Operations | I13: emp011@abc.com | J13: =ROUND(YEARFRAC('Employee data'!$G13,TODAY()),2) -> 7.49 | K13: 4.1 | L13: 95 | M13: 46000 | N13: 15500 | O13: 6500 | P13: =IF('Employee data'!$M13>=50000,"10%","5%") -> 5% | Q13: =M13*P13 -> 2300 | R13: =IF(AND('Employee data'!$K13>=4,'Employee data'!$L13>=95),5000,0) -> 5000 | S13: =M13+N13+O13+Q13+R13 -> 75300 | T13: 12 | U13: ='Employee data'!$M13/'Employee data'!$T13 -> 3833.3333 | V13: 1300 | W13: =IF('Employee data'!$S13>=80000,20%,IF('Employee data'!$S13>=50000,10%,5%)) -> 0.1 | X13: =S13*W13 -> 7530 | Y13: =IF(OR('Employee data'!$J13>5,'Employee data'!$L13>98),"Eligible","Not Eligible") -> Eligible | Z13: =S13-X13-U13-V13 -> 62636.667
A14: EMP012 | B14: Nandhini K | C14: D006 | D14: Support Analyst | E14: F | F14: 35296 | G14: 44445 | H14: =VLOOKUP(TRIM('Employee data'!$C14),$A$108:$B$113,2,FALSE) -> Support | I14: emp012@abc.com | J14: =ROUND(YEARFRAC('Employee data'!$G14,TODAY()),2) -> 4.92 | K14: 3.6 | L14: 92 | M14: 34000 | N14: 11500 | O14: 4800 | P14: =IF('Employee data'!$M14>=50000,"10%","5%") -> 5% | Q14: =M14*P14 -> 1700 | R14: =IF(AND('Employee data'!$K14>=4,'Employee data'!$L14>=95),5000,0) -> 0 | S14: =M14+N14+O14+Q14+R14 -> 52000 | T14: 12 | U14: ='Employee data'!$M14/'Employee data'!$T14 -> 2833.3333 | V14: 900 | W14: =IF('Employee data'!$S14>=80000,20%,IF('Employee data'!$S14>=50000,10%,5%)) -> 0.1 | X14: =S14*W14 -> 5200 | Y14: =IF(OR('Employee data'!$J14>5,'Employee data'!$L14>98),"Eligible","Not Eligible") -> Not Eligible | Z14: =S14-X14-U14-V14 -> 43066.667
... A102: EMP100 | B102: Komala S | C102: D002 | D102: HR Coordinator | E102: F | F102: 35487 | G102: 45040 | H102: =VLOOKUP(TRIM('Employee data'!$C102),$A$108:$B$113,2,FALSE) -> HR | I102: emp100@abc.com | J102: =ROUND(YEARFRAC('Employee data'!$G102,TODAY()),2) -> 3.28 | K102: 3.6 | L102: 91 | M102: 30000 | N102: 9800 | O102: 3600 | P102: =IF('Employee data'!$M102>=50000,"10%","5%") -> 5% | Q102: =M102*P102 -> 1500 | R102: =IF(AND('Employee data'!$K102>=4,'Employee data'!$L102>=95),5000,0) -> 0 | S102: =M102+N102+O102+Q102+R102 -> 44900 | T102: 12 | U102: ='Employee data'!$M102/'Employee data'!$T102 -> 2500 | V102: 750 | W102: =IF('Employee data'!$S102>=80000,20%,IF('Employee data'!$S102>=50000,10%,5%)) -> 0.05 | X102: =S102*W102 -> 2245 | Y102: =IF(OR('Employee data'!$J102>5,'Employee data'!$L102>98),"Eligible","Not Eligible") -> Not Eligible | Z102: =S102-X102-U102-V102 -> 39405
L105: 12. Dept wise salary (SUMIFS) | N105: 14. Dept wise average salary (AVGIFS)
A106: DEPT | D106: 8. LOOKUP | H106: 9. INDEX, MATCH | L106: DEPT | M106: Salary | N106: Column1 | O106: Salary
A107: Department | B107: Dept ID | D107: Slab | E107: Gross Salary | F107: % | H107: EmpID | I107: EMP048 | L107: IT | M107: =SUMIFS('Employee data'!$S$3:$S$102,'Employee data'!$C$3:$C$102,"D001") -> 1738800 | N107: IT | O107: =AVERAGEIFS('Employee data'!$S$3:$S$102,'Employee data'!$C$3:$C$102,"D001") -> 96600
A108: D001 | B108: IT | D108: Slab1 | E108: 0 | F108: 5 | H108: Designation | I108: =INDEX($D$3:$D$102,MATCH(I107,$A$3:$A$102,0)) -> Customer Success | L108: HR | M108: =SUMIFS('Employee data'!$S$3:$S$102,'Employee data'!$C$3:$C$102,"D002") -> 1191400 | N108: HR | O108: =AVERAGEIFS('Employee data'!$S$3:$S$102,'Employee data'!$C$3:$C$102,"D002") -> 66188.889
A109: D002 | B109: HR | D109: Slab2 | E109: 50000 | F109: 10 | L109: Finance | M109: =SUMIFS('Employee data'!$S$3:$S$102,'Employee data'!$C$3:$C$102,"D003") -> 1605500 | N109: Finance | O109: =AVERAGEIFS('Employee data'!$S$3:$S$102,'Employee data'!$C$3:$C$102,"D003") -> 100343.75
A110: D003 | B110: Finance | D110: Slab3 | E110: 80000 | F110: 20 | L110: Sales | M110: =SUMIFS('Employee data'!$S$3:$S$102,'Employee data'!$C$3:$C$102,"D004") -> 963100 | N110: Sales | O110: =AVERAGEIFS('Employee data'!$S$3:$S$102,'Employee data'!$C$3:$C$102,"D004") -> 60193.75
A111: D004 | B111: Sales | H111: Data Validation | L111: Operations | M111: =SUMIFS('Employee data'!$S$3:$S$102,'Employee data'!$C$3:$C$102,"D005") -> 1246750 | N111: Operations | O111: =AVERAGEIFS('Employee data'!$S$3:$S$102,'Employee data'!$C$3:$C$102,"D005") -> 77921.875
A112: D005 | B112: Operations | G112: 10 | H112: Department | I112: HR | L112: Support | M112: =SUMIFS('Employee data'!$S$3:$S$102,'Employee data'!$C$3:$C$102,"D006") -> 864050 | N112: Support | O112: =AVERAGEIFS('Employee data'!$S$3:$S$102,'Employee data'!$C$3:$C$102,"D006") -> 54003.125
A113: D006 | B113: Support | E113: Gross salary | F113: 65000 | G113: 11 | H113: Designation | I113: Recruiter
E114: Tax % | F114: =LOOKUP(F113,Table4[Gross Salary],Table4[%]) -> 10
A115: 5. VLOOKUP | E115: Slab | F115: =LOOKUP(F114,Table4[Gross Salary],Table4[Slab]) -> Slab1 | L115: 13. Countifs for >50000 dept wise
A116: Column1 | B116: Column2 | L116: Dept | M116: Count
A117: Emp ID | B117: EMP033 | L117: IT | M117: =COUNTIFS('Employee data'!$C$3:$C$102,"D001",'Employee data'!$S$3:$S$102,">50000") -> 18
A118: Name | B118: =VLOOKUP(B117,$A$3:$Z$102,2,FALSE) -> Pradeep S | L118: HR | M118: =COUNTIFS('Employee data'!$C$3:$C$102,"D002",'Employee data'!$S$3:$S$102,">50000") -> 14
A119: Email ID | B119: =VLOOKUP(B117,$A$3:$Z$102,9,FALSE) -> emp033@abc.com | L119: Finance | M119: =COUNTIFS('Employee data'!$C$3:$C$102,"D003",'Employee data'!$S$3:$S$102,">50000") -> 16
L120: Sales | M120: =COUNTIFS('Employee data'!$C$3:$C$102,"D004",'Employee data'!$S$3:$S$102,">50000") -> 6
L121: Operations | M121: =COUNTIFS('Employee data'!$C$3:$C$102,"D005",'Employee data'!$S$3:$S$102,">50000") -> 16
A122: 15. Payroll search | L122: Support | M122: =COUNTIFS('Employee data'!$C$3:$C$102,"D006",'Employee data'!$S$3:$S$102,">50000") -> 14
A123: Content | B123: Employee Details
A124: Emp ID | B124: EMP048
A125: Emp Name | B125: =VLOOKUP(B124,'Employee data'!$A$3:$Z$102,2) -> Anjali N
A126: Department | B126: =VLOOKUP(B124,'Employee data'!$A$3:$Z$102,8) -> Support
A127: Designation | B127: =VLOOKUP(B124,'Employee data'!$A$3:$Z$102,4) -> Customer Success
A128: Basic Salary | B128: =VLOOKUP(B124,'Employee data'!$A$3:$Z$102,13) -> 35500
A129: Bonus | B129: =VLOOKUP(B124,'Employee data'!$A$3:$Z$102,17) -> 1775
...

Sheet Pivot
A3: Row Labels | B3: Count of Gross Salary | C3: Sum of Gross Salary | D3: Average of Gross Salary
A4: Finance | B4: 16 | C4: 1439000 | D4: 89937.5
A5: HR | B5: 18 | C5: 1135400 | D5: 63077.778
A6: IT | B6: 18 | C6: 1563000 | D6: 86833.333
A7: Operations | B7: 16 | C7: 1126000 | D7: 70375
A8: Sales | B8: 16 | C8: 919800 | D8: 57487.5
A9: Support | B9: 16 | C9: 835800 | D9: 52237.5
A10: Grand Total | B10: 100 | C10: 7019000 | D10: 70190
A16: Row Labels | B16: Sum of Gross Salary
A17: Finance | B17: 1439000
A18: HR | B18: 1135400
A19: IT | B19: 1563000
A20: Operations | B20: 1126000
A21: Sales | B21: 919800
A22: Support | B22: 835800
A23: Grand Total | B23: 7019000

Sheet Salary Dashboard
A2: Total Employee | B2: Total Salary | C2: Average Salary | D2: Max of Salary | E2: Min of Salary
A3: 100 | B3: 7019000 | C3: 70190 | D3: 123000 | E3: 42000
A8: Row Labels | B8: Total Salary | G8: Row Labels | H8: Total Employee
A9: Finance | B9: 1439000 | G9: Finance | H9: 16
A10: HR | B10: 1135400 | G10: HR | H10: 18
A11: IT | B11: 1563000 | G11: IT | H11: 18
A12: Operations | B12: 1126000 | G12: Operations | H12: 16
A13: Sales | B13: 919800 | G13: Sales | H13: 16
A14: Support | B14: 835800 | G14: Support | H14: 16
A15: Grand Total | B15: 7019000 | G15: Grand Total | H15: 100

Sheet Payroll Summary
A3: Total Employees | B3: Total Gross Salary | C3: Total Bonus
A4: 100 | B4: 7609600 | C4: 350600
A6: Total PF | B6: Total Tax | C6: Total Net Salary
A7: 392500 | B7: 1108837.5 | C7: 5952262.5
A9: Average Salary | B9: Highest Paid Employee | C9: Lowest Paid Employee
A10: 59522.625 | B10: 98633.333 | C10: 38160.833

Sheet Dept,Desig
A1: Department | B1: Sales | C1: Operations | D1: IT | E1: Finance | F1: HR | G1: Marketing
A2: HR | B2: Sales Executive | C2: Coordinator | D2: Support Engineer | E2: Accountant | F2: Analyst | G2: Account Manager
A3: Finance | B3: Sales Officer | C3: Supervisor | D3: Developer | E3: Senior Accountant | F3: HR Analyst | G3: Analyst
A4: IT | B4: Sales Coordinator | C4: Operations Executive | D4: Senior Developer | E4: Finance Analyst | F4: HR Executive | G4: Executive
A5: Sales | B5: Sales Manager | C5: Team Lead | D5: Data Engineer | E5: Auditor | F5: Recruiter | G5: Coordinator
A6: Marketing | C6: Operations Manager | D6: QA Analyst | E6: Payroll Executive | F6: HR Assistant | G6: Specialist
A7: Operations | C7: Process Associate | D7: Cloud Engineer | E7: Tax Analyst | F7: HR Manager | G7: Manager
C8: Operations Analyst | D8: System Admin | E8: Accounts Executive | F8: Talent Acquisition
C9: Shift Supervisor | D9: Data Analyst | E9: Senior Auditor | F9: HR Coordinator
D10: Backend Developer
D11: Customer Support
D12: Support Analyst
D13: Senior Support
D14: Technical Support
D15: Customer Success
